Workbook

Sheet COMPANY OVERVIEW

Sheet PROFIT & LOSS
C3: PROFIT & LOSS STATEMENT
C4: Consolidated Figures in Rs. Crores
C5: Particulars | D5: 41699 | E5: 42064 | F5: 42430 | G5: 42795 | H5: 43160 | I5: 43525 | J5: 43891 | K5: 44256 | L5: 44621 | M5: 44986 | N5: 45352 | O5: 45717
C6: Sales + | D6: 427.75 | E6: 978.84 | F6: 1270.19 | G6: 1734.67 | H6: 2033.13 | I6: 1997.53 | J6: 456.83 | K6: 70.8 | L6: 59.68 | M6: 23.02 | N6: 2.3 | O6: 0.98
C7: Expenses + | D7: 421.83 | E7: 963.71 | F7: 1241.47 | G7: 1681.03 | H7: 1975.34 | I7: 1921.41 | J7: 574.77 | K7: 214 | L7: 119.93 | M7: 29.95 | N7: 4.56 | O7: 2.14
C8: Operating Profit | D8: 5.92 | E8: 15.13 | F8: 28.72 | G8: 53.64 | H8: 57.79 | I8: 76.12 | J8: -117.94 | K8: -143.2 | L8: -60.25 | M8: -6.93 | N8: -2.26 | O8: -1.16
C9: OPM % | D9: 0.0138 | E9: 0.0155 | F9: 0.0226 | G9: 0.0309 | H9: 0.0284 | I9: 0.0381 | J9: -0.2582 | K9: -2.0226 | L9: -1.0096 | M9: -0.301 | N9: -0.9826 | O9: -1.1837
C10: Other Income + | D10: 0.36 | E10: 0.53 | F10: 0.89 | G10: 1.35 | H10: 6.68 | I10: 5.59 | J10: -19.88 | K10: -2.67 | L10: 0.23 | M10: 0.11 | N10: 0.82 | O10: 0.2
C11: Interest | D11: 3.99 | E11: 7.98 | F11: 12.19 | G11: 13.24 | H11: 19.11 | I11: 24.05 | J11: 15.9 | K11: 0.2 | L11: 0.6 | M11: 1.64 | N11: 0 | O11: 0
C12: Depreciation | D12: 0.22 | E12: 0.63 | F12: 0.78 | G12: 2.41 | H12: 4.99 | I12: 12.01 | J12: 13.37 | K12: 12.59 | L12: 11.28 | M12: 5.77 | N12: 8.36 | O12: 5.41
C13: Profit before tax | D13: 2.07 | E13: 7.05 | F13: 16.64 | G13: 39.34 | H13: 40.37 | I13: 45.65 | J13: -167.09 | K13: -158.66 | L13: -71.9 | M13: -14.23 | N13: -9.8 | O13: -6.37
C14: Tax % | D14: 0.1594 | E14: 0.122 | F14: 0.1034 | G14: 0.0887 | H14: 0.1878 | I14: 0.1967 | J14: -0.0045 | K14: -0.0107 | L14: -0.0032 | M14: 0.208 | N14: -0.0592 | O14: 0.011
C15: Net Profit + | D15: 1.73 | E15: 6.18 | F15: 14.93 | G15: 35.84 | H15: 32.8 | I15: 36.67 | J15: -166.35 | K15: -156.95 | L15: -71.66 | M15: -17.19 | N15: -9.22 | O15: -6.44
C16: EPS in Rs | D16: 1.59 | E16: 5.67 | F16: 13.7 | G16: 26.67 | H16: 24.41 | I16: 27.29 | J16: -106.11 | K16: -100.12 | L16: -45.71 | M16: -10.97 | N16: -5.88 | O16: -4.11
C17: Dividend Payout % | D17: 0 | E17: 0 | F17: 0 | G17: 0 | H17: 0.041 | I17: 0.0183 | J17: 0 | K17: 0 | L17: 0 | M17: 0 | N17: 0 | O17: 0

Sheet BALANCE SHEET
C3: BALANCE SHEET
C4: Consolidated Figures in Rs. Crores
C5: Particulars | D5: 41699 | E5: 42064 | F5: 42430 | G5: 42795 | H5: 43160 | I5: 43525 | J5: 43891 | K5: 44256 | L5: 44621 | M5: 44986 | N5: 45352 | O5: 45717
C6: Equity Capital | D6: 10.9 | E6: 10.9 | F6: 10.9 | G6: 13.44 | H6: 13.44 | I6: 13.44 | J6: 15.68 | K6: 15.68 | L6: 15.68 | M6: 15.68 | N6: 15.68 | O6: 15.68
C7: Reserves | D7: 31.91 | E7: 37.3 | F7: 51.68 | G7: 134 | H7: 215.84 | I7: 255.27 | J7: 92.94 | K7: -65.84 | L7: -137.22 | M7: -154.41 | N7: -163.64 | O7: -170.08
C8: Borrowings + | D8: 26.19 | E8: 51.15 | F8: 102.07 | G8: 151.02 | H8: 120.68 | I8: 148.02 | J8: 238.07 | K8: 233.16 | L8: 233.54 | M8: 235.85 | N8: 235.85 | O8: 235.85
C9: Other Liabilities + | D9: 40.59 | E9: 172.97 | F9: 213.71 | G9: 209.04 | H9: 143.7 | I9: 176.67 | J9: 95.26 | K9: 12.45 | L9: 6.43 | M9: 11.75 | N9: 17.87 | O9: 9.97
C10: Total Liabilities | D10: 109.59 | E10: 272.32 | F10: 378.36 | G10: 507.5 | H10: 493.66 | I10: 593.4 | J10: 441.95 | K10: 195.45 | L10: 118.43 | M10: 108.87 | N10: 105.76 | O10: 91.42
C11: Fixed Assets + | D11: 1.14 | E11: 2.62 | F11: 4.25 | G11: 23.88 | H11: 56.93 | I11: 97.04 | J11: 90.13 | K11: 71.25 | L11: 61.7 | M11: 55.92 | N11: 47.55 | O11: 42.14
C12: CWIP | D12: 0 | E12: 0.4 | F12: 0.52 | G12: 16.08 | H12: 9.84 | I12: 10.43 | J12: 9.47 | K12: 8.42 | L12: 6.27 | M12: 6.27 | N12: 6.27 | O12: 6.27
C13: Investments | D13: 19.93 | E13: 0 | F13: 36.45 | G13: 0.05 | H13: 0.45 | I13: 2.62 | J13: 11.86 | K13: 11.86 | L13: 11.86 | M13: 12.47 | N13: 12.47 | O13: 12.47
C14: Other Assets + | D14: 88.52 | E14: 269.3 | F14: 337.14 | G14: 467.49 | H14: 426.44 | I14: 483.31 | J14: 330.49 | K14: 103.92 | L14: 38.6 | M14: 34.21 | N14: 39.47 | O14: 30.54
C15: Total Assets | D15: 109.59 | E15: 272.32 | F15: 378.36 | G15: 507.5 | H15: 493.66 | I15: 593.4 | J15: 441.95 | K15: 195.45 | L15: 118.43 | M15: 108.87 | N15: 105.76 | O15: 91.42

Sheet CASH FLOW 
C3: CASH FLOW STATEMENT
C4: Consolidated Figures in Rs. Crores
C5: Particulars | D5: 41699 | E5: 42064 | F5: 42430 | G5: 42795 | H5: 43160 | I5: 43525 | J5: 43891 | K5: 44256 | L5: 44621 | M5: 44986 | N5: 45352 | O5: 45717
C6: Cash from Operating Activity + | D6: -4.03 | E6: -31.47 | F6: 0.8 | G6: 14.12 | H6: -4.33 | I6: 45.23 | J6: 25.59 | K6: 1.06 | L6: -1.16 | M6: 1.21 | N6: 4.81 | O6: -8.4
C7: Cash from Investing Activity + | D7: -8.73 | E7: 17.42 | F7: -38.14 | G7: -56.12 | H7: 6.37 | I7: -49.15 | J7: 8.35 | K7: 3.4 | L7: 0.58 | M7: -0.07 | N7: 0.82 | O7: 0.2
C8: Cash from Financing Activity + | D8: 13.53 | E8: 16.97 | F8: 38.74 | G8: 40.36 | H8: 0.13 | I8: 3.3 | J8: -34.19 | K8: -4.94 | L8: 0.17 | M8: 0.67 | N8: 0 | O8: 0
C9: Net Cash Flow | D9: 0.77 | E9: 2.93 | F9: 1.4 | G9: -1.64 | H9: 2.17 | I9: -0.63 | J9: -0.25 | K9: -0.48 | L9: -0.42 | M9: 1.81 | N9: 5.63 | O9: -8.2
C10: Free Cash Flow | D10: -4.1 | E10: -33.98 | F10: -1.72 | G10: -23.37 | H10: -37.55 | I10: -6.06 | J10: 20.1 | K10: 4.96 | L10: -0.73 | M10: 1.21 | N10: 4.81 | O10: -8.4
C11: CFO/OP | D11: -0.62 | E11: -2.02 | F11: 0.09 | G11: 0.3 | H11: -0.02 | I11: 0.6 | J11: -0.22 | K11: -0.01 | L11: 0.02 | M11: -0.17 | N11: -2.13 | O11: 7.24

Sheet INCOME STATEMENT ANALYSIS
C3: INCOME STATEMENT ANALYSIS
C4: Consolidated Figures in Rs. Crores
C5: PARTICULARS | D5: 2014 | E5: 2015 | F5: 2016 | G5: 2017 | H5: 2018 | I5: 2019 | J5: 2020 | K5: 2021 | L5: 2022 | M5: 2023 | N5: 2024 | O5: 2025
C6: Revenue | D6: 427.75 | E6: 978.84 | F6: 1270.19 | G6: 1734.67 | H6: 2033.13 | I6: 1997.53 | J6: 456.83 | K6: 70.8 | L6: 59.68 | M6: 23.02 | N6: 2.3 | O6: 0.98
C7: Revenue Growth % | D7: 0 | E7: =(E6-D6)/D6 -> 1.288346 | F7: =(F6-E6)/E6 -> 0.29764824 | G7: =(G6-F6)/F6 -> 0.36567758 | H7: =(H6-G6)/G6 -> 0.17205578 | I7: =(I6-H6)/H6 -> -0.017509948 | J7: =(J6-I6)/I6 -> -0.77130256 | K7: =(K6-J6)/J6 -> -0.84501893 | L7: =(L6-K6)/K6 -> -0.15706215 | ... O7: =(O6-N6)/N6 -> -0.57391304
C8: Expenses | D8: 421.83 | E8: 963.71 | F8: 1241.47 | G8: 1681.03 | H8: 1975.34 | I8: 1921.41 | J8: 574.77 | K8: 214 | L8: 119.93 | M8: 29.95 | N8: 4.56 | O8: 2.14
C9: Expense Growth % | D9: 0 | E9: =(E8-D8)/D8 -> 1.2845933 | F9: =(F8-E8)/E8 -> 0.28821949 | G9: =(G8-F8)/F8 -> 0.35406413 | H9: =(H8-G8)/G8 -> 0.17507718 | I9: =(I8-H8)/H8 -> -0.027301629 | J9: =(J8-I8)/I8 -> -0.70086031 | K9: =(K8-J8)/J8 -> -0.62767716 | L9: =(L8-K8)/K8 -> -0.43957944 | ... O9: =(O8-N8)/N8 -> -0.53070175
C10: Expense to Sales % | D10: =D8/D6 -> 0.98616014 | E10: =E8/E6 -> 0.98454293 | F10: =F8/F6 -> 0.97738921 | G10: =G8/G6 -> 0.96907769 | H10: =H8/H6 -> 0.97157585 | I10: =I8/I6 -> 0.96189294 | J10: =J8/J6 -> 1.2581704 | K10: =K8/K6 -> 3.0225989 | ... O10: =O8/O6 -> 2.1836735
C11: Operating Profit | D11: 5.92 | E11: 15.13 | F11: 28.72 | G11: 53.64 | H11: 57.79 | I11: 76.12 | J11: -117.94 | K11: -143.2 | L11: -60.25 | M11: -6.93 | N11: -2.26 | O11: -1.16
C12: Operating Profit Growth % | D12: 0 | E12: =(E11-D11)/D11 -> 1.5557432 | F12: =(F11-E11)/E11 -> 0.89821547 | G12: =(G11-F11)/F11 -> 0.86768802 | H12: =(H11-G11)/G11 -> 0.077367636 | I12: =(I11-H11)/H11 -> 0.3171829 | J12: =(J11-I11)/I11 -> -2.5493957 | K12: =(K11-J11)/J11 -> 0.2141767 | L12: =(L11-K11)/K11 -> -0.57925978 | ... O12: =(O11-N11)/N11 -> -0.48672566
C13: OPM % | D13: =D11/D6 -> 0.01383986 | E13: =E11/E6 -> 0.015457072 | F13: =F11/F6 -> 0.022610791 | G13: =G11/G6 -> 0.030922308 | H13: =H11/H6 -> 0.028424154 | I13: =I11/I6 -> 0.038107062 | J13: =J11/J6 -> -0.25817044 | K13: =K11/K6 -> -2.0225989 | ... O13: =O11/O6 -> -1.1836735
C14: Other Income | D14: 0.36 | E14: 0.53 | F14: 0.89 | G14: 1.35 | H14: 6.68 | I14: 5.59 | J14: -19.88 | K14: -2.67 | L14: 0.23 | M14: 0.11 | N14: 0.82 | O14: 0.2
C15: Other Income to PBT % | D15: =D14/D20 -> 0.17391304 | E15: =E14/E20 -> 0.075177305 | F15: =F14/F20 -> 0.053485577 | G15: =G14/G20 -> 0.034316218 | H15: =H14/H20 -> 0.16546941 | I15: =I14/I20 -> 0.12245345 | J15: =J14/J20 -> 0.1189778 | K15: =K14/K20 -> 0.016828438 | ... O15: =O14/O20 -> -0.031397174
C16: Interest | D16: 3.99 | E16: 7.98 | F16: 12.19 | G16: 13.24 | H16: 19.11 | I16: 24.05 | J16: 15.9 | K16: 0.2 | L16: 0.6 | M16: 1.64 | N16: 0 | O16: 0
C17: Interest to Sales % | D17: =D16/D6 -> 0.0093278784 | E17: =E16/E6 -> 0.008152507 | F17: =F16/F6 -> 0.0095969894 | G17: =G16/G6 -> 0.0076325756 | H17: =H16/H6 -> 0.0093993006 | I17: =I16/I6 -> 0.012039869 | J17: =J16/J6 -> 0.03480507 | K17: =K16/K6 -> 0.0028248588 | ... O17: =O16/O6 -> 0
C18: Depreciation | D18: 0.22 | E18: 0.63 | F18: 0.78 | G18: 2.41 | H18: 4.99 | I18: 12.01 | J18: 13.37 | K18: 12.59 | L18: 11.28 | M18: 5.77 | N18: 8.36 | O18: 5.41
C19: Depreciation to Sales % | D19: =D18/D6 -> 0.00051431911 | E19: =E18/E6 -> 0.00064361898 | F19: =F18/F6 -> 0.00061408136 | G19: =G18/G6 -> 0.0013893132 | H19: =H18/H6 -> 0.0024543438 | I19: =I18/I6 -> 0.0060124253 | J19: =J18/J6 -> 0.029266905 | K19: =K18/K6 -> 0.17782486 | ... O19: =O18/O6 -> 5.5204082
C20: PBT | D20: 2.07 | E20: 7.05 | F20: 16.64 | G20: 39.34 | H20: 40.37 | I20: 45.65 | J20: -167.09 | K20: -158.66 | L20: -71.9 | M20: -14.23 | N20: -9.8 | O20: -6.37
C21: PBT Growth % | D21: 0 | E21: =(E20-D20)/D20 -> 2.4057971 | F21: =(F20-E20)/E20 -> 1.3602837 | G21: =(G20-F20)/F20 -> 1.3641827 | H21: =(H20-G20)/G20 -> 0.026182003 | I21: =(I20-H20)/H20 -> 0.13079019 | J21: =(J20-I20)/I20 -> -4.660241 | K21: =(K20-J20)/J20 -> -0.050451852 | L21: =(L20-K20)/K20 -> -0.5468297 | ... O21: =(O20-N20)/N20 -> -0.35
C22: Tax % | D22: 0.1594 | E22: 0.122 | F22: 0.1034 | G22: 0.0887 | H22: 0.1878 | I22: 0.1967 | J22: -0.0045 | K22: -0.0107 | L22: -0.0032 | M22: 0.208 | N22: -0.0592 | O22: 0.011
C23: Net Profit | D23: 1.73 | E23: 6.18 | F23: 14.93 | G23: 35.84 | H23: 32.8 | I23: 36.67 | J23: -166.35 | K23: -156.95 | L23: -71.66 | M23: -17.19 | N23: -9.22 | O23: -6.44
C24: Net Profit Growth % | D24: 0 | E24: =(E23-D23)/D23 -> 2.5722543 | F24: =(F23-E23)/E23 -> 1.4158576 | G24: =(G23-F23)/F23 -> 1.4005358 | H24: =(H23-G23)/G23 -> -0.084821429 | I24: =(I23-H23)/H23 -> 0.1179878 | J24: =(J23-I23)/I23 -> -5.5364058 | K24: =(K23-J23)/J23 -> -0.056507364 | L24: =(L23-K23)/K23 -> -0.54342147 | ... O24: =(O23-N23)/N23 -> -0.30151844
C25: Net Profit Margin % | D25: =D23/D6 -> 0.0040444185 | E25: =E23/E6 -> 0.0063135957 | F25: =F23/F6 -> 0.011754147 | G25: =G23/G6 -> 0.02066099 | H25: =H23/H6 -> 0.016132761 | I25: =I23/I6 -> 0.018357672 | J25: =J23/J6 -> -0.36413983 | K25: =K23/K6 -> -2.2168079 | ... O25: =O23/O6 -> -6.5714286
C26: EPS | D26: 1.59 | E26: 5.67 | F26: 13.7 | G26: 26.67 | H26: 24.41 | I26: 27.29 | J26: -106.11 | K26: -100.12 | L26: -45.71 | M26: -10.97 | N26: -5.88 | O26: -4.11
C27: EPS Growth % | D27: 0 | E27: =(E26-D26)/D26 -> 2.5660377 | F27: =(F26-E26)/E26 -> 1.4162257 | G27: =(G26-F26)/F26 -> 0.94671533 | H27: =(H26-G26)/G26 -> -0.084739408 | I27: =(I26-H26)/H26 -> 0.11798443 | J27: =(J26-I26)/I26 -> -4.8882374 | K27: =(K26-J26)/J26 -> -0.056450853 | L27: =(L26-K26)/K26 -> -0.54344786 | ... O27: =(O26-N26)/N26 -> -0.30102041
C28: Dividend Payout % | D28: 0 | E28: 0 | F28: 0 | G28: 0 | H28: 0.041 | I28: 0.0183 | J28: 0 | K28: 0 | L28: 0 | M28: 0 | N28: 0 | O28: 0

Sheet BALANCE SHEET ANALYSIS
C3: BALANCE SHEET ANALYSIS | S3: S
C4: Consolidated Figures in Rs. Crores
C5: PARTICULARS | D5: 2014 | E5: 2015 | F5: 2016 | G5: 2017 | H5: 2018 | I5: 2019 | J5: 2020 | K5: 2021 | L5: 2022 | M5: 2023 | N5: 2024 | O5: 2025
C6: Equity Capital | D6: 10.9 | E6: 10.9 | F6: 10.9 | G6: 13.44 | H6: 13.44 | I6: 13.44 | J6: 15.68 | K6: 15.68 | L6: 15.68 | M6: 15.68 | N6: 15.68 | O6: 15.68
C7: Equity Capital Growth % | D7: 0 | E7: =(E6-D6)/D6 -> 0 | F7: =(F6-E6)/E6 -> 0 | G7: =(G6-F6)/F6 -> 0.23302752 | H7: =(H6-G6)/G6 -> 0 | I7: =(I6-H6)/H6 -> 0 | J7: =(J6-I6)/I6 -> 0.16666667 | K7: =(K6-J6)/J6 -> 0 | L7: =(L6-K6)/K6 -> 0 | ... O7: =(O6-N6)/N6 -> 0
C8: Reserves | D8: 31.91 | E8: 37.3 | F8: 51.68 | G8: 134 | H8: 215.84 | I8: 255.27 | J8: 92.94 | K8: -65.84 | L8: -137.22 | M8: -154.41 | N8: -163.64 | O8: -170.08
C9: Reserves Growth % | D9: 0 | E9: =(E8-D8)/D8 -> 0.16891257 | F9: =(F8-E8)/E8 -> 0.38552279 | G9: =(G8-F8)/F8 -> 1.5928793 | H9: =(H8-G8)/G8 -> 0.61074627 | I9: =(I8-H8)/H8 -> 0.18268162 | J9: =(J8-I8)/I8 -> -0.63591491 | K9: =(K8-J8)/J8 -> -1.708414 | L9: =(L8-K8)/K8 -> 1.0841434 | ... O9: =(O8-N8)/N8 -> 0.039354681
C10: Total Equity (Equity + Reserves) | D10: =D8+D6 -> 42.81 | E10: =E8+E6 -> 48.2 | F10: =F8+F6 -> 62.58 | G10: =G8+G6 -> 147.44 | H10: =H8+H6 -> 229.28 | I10: =I8+I6 -> 268.71 | J10: =J8+J6 -> 108.62 | K10: =K8+K6 -> -50.16 | ... O10: =O8+O6 -> -154.4
C11: Equity Growth % | D11: 0 | E11: =(E10-D10)/D10 -> 0.12590516 | F11: =(F10-E10)/E10 -> 0.29834025 | G11: =(G10-F10)/F10 -> 1.3560243 | H11: =(H10-G10)/G10 -> 0.55507325 | I11: =(I10-H10)/H10 -> 0.17197313 | J11: =(J10-I10)/I10 -> -0.59577239 | K11: =(K10-J10)/J10 -> -1.4617934 | L11: =(L10-K10)/K10 -> 1.4230463 | ... O11: =(O10-N10)/N10 -> 0.043525277
C12: Borrowings | D12: 26.19 | E12: 51.15 | F12: 102.07 | G12: 151.02 | H12: 120.68 | I12: 148.02 | J12: 238.07 | K12: 233.16 | L12: 233.54 | M12: 235.85 | N12: 235.85 | O12: 235.85
C13: Borrowing Growth % | D13: 0 | E13: =(E12-D12)/D12 -> 0.95303551 | F13: =(F12-E12)/E12 -> 0.99550342 | G13: =(G12-F12)/F12 -> 0.47957284 | H13: =(H12-G12)/G12 -> -0.20090054 | I13: =(I12-H12)/H12 -> 0.22654955 | J13: =(J12-I12)/I12 -> 0.60836373 | K13: =(K12-J12)/J12 -> -0.020624186 | L13: =(L12-K12)/K12 -> 0.0016297821 | ... O13: =(O12-N12)/N12 -> 0
C14: Debt to Assets % | D14: =D12/D27 -> 0.23898166 | E14: =E12/E27 -> 0.18783049 | F14: =F12/F27 -> 0.26976953 | G14: =G12/G27 -> 0.29757635 | H14: =H12/H27 -> 0.24445975 | I14: =I12/I27 -> 0.24944388 | J14: =J12/J27 -> 0.53868085 | K14: =K12/K27 -> 1.1929394 | ... O14: =O12/O27 -> 2.5798512
C15: Other Liabilities | D15: 40.59 | E15: 172.97 | F15: 213.71 | G15: 209.04 | H15: 143.7 | I15: 176.67 | J15: 95.26 | K15: 12.45 | L15: 6.43 | M15: 11.75 | N15: 17.87 | O15: 9.97
C16: Other Liabilities Growth % | D16: 0 | E16: =(E15-D15)/D15 -> 3.2613944 | F16: =(F15-E15)/E15 -> 0.23553217 | G16: =(G15-F15)/F15 -> -0.021852042 | H16: =(H15-G15)/G15 -> -0.31257176 | I16: =(I15-H15)/H15 -> 0.22943633 | J16: =(J15-I15)/I15 -> -0.46080263 | K16: =(K15-J15)/J15 -> -0.86930506 | L16: =(L15-K15)/K15 -> -0.48353414 | ... O16: =(O15-N15)/N15 -> -0.4420817
C17: Total Liabilities | D17: 109.59 | E17: 272.32 | F17: 378.36 | G17: 507.5 | H17: 493.66 | I17: 593.4 | J17: 441.95 | K17: 195.45 | L17: 118.43 | M17: 108.87 | N17: 105.76 | O17: 91.42
C18: Liability Growth % | D18: 0 | E18: =(E17-D17)/D17 -> 1.4848983 | F18: =(F17-E17)/E17 -> 0.38939483 | G18: =(G17-F17)/F17 -> 0.34131515 | H18: =(H17-G17)/G17 -> -0.027270936 | I18: =(I17-H17)/H17 -> 0.20204189 | J18: =(J17-I17)/I17 -> -0.25522413 | K18: =(K17-J17)/J17 -> -0.5577554 | L18: =(L17-K17)/K17 -> -0.39406498 | ... O18: =(O17-N17)/N17 -> -0.13559002
C19: Fixed Assets | D19: 1.14 | E19: 2.62 | F19: 4.25 | G19: 23.88 | H19: 56.93 | I19: 97.04 | J19: 90.13 | K19: 71.25 | L19: 61.7 | M19: 55.92 | N19: 47.55 | O19: 42.14
C20: Fixed Asset to Total Assets % | D20: =D19/D27 -> 0.010402409 | E20: =E19/E27 -> 0.0096210341 | F20: =F19/F27 -> 0.011232688 | G20: =G19/G27 -> 0.047054187 | H20: =H19/H27 -> 0.11532229 | I20: =I19/I27 -> 0.16353219 | J20: =J19/J27 -> 0.2039371 | K20: =K19/K27 -> 0.36454336 | ... O20: =O19/O27 -> 0.46094946
C21: CWIP | D21: 0 | E21: 0.4 | F21: 0.52 | G21: 16.08 | H21: 9.84 | I21: 10.43 | J21: 9.47 | K21: 8.42 | L21: 6.27 | M21: 6.27 | N21: 6.27 | O21: 6.27
C22: CWIP to Total Assets % | D22: =D21/D27 -> 0 | E22: =E21/E27 -> 0.0014688602 | F22: =F21/F27 -> 0.0013743525 | G22: =G21/G27 -> 0.031684729 | H22: =H21/H27 -> 0.019932747 | I22: =I21/I27 -> 0.017576677 | J22: =J21/J27 -> 0.021427763 | K22: =K21/K27 -> 0.043080072 | ... O22: =O21/O27 -> 0.068584555
C23: Investments | D23: 19.93 | E23: 0 | F23: 36.45 | G23: 0.05 | H23: 0.45 | I23: 2.62 | J23: 11.86 | K23: 11.86 | L23: 11.86 | M23: 12.47 | N23: 12.47 | O23: 12.47
C24: Investment to Total Assets % | D24: =D23/D27 -> 0.18185966 | E24: =E23/E27 -> 0 | F24: =F23/F27 -> 0.096336822 | G24: =G23/G27 -> 9.8522167e-05 | H24: =H23/H27 -> 0.00091155856 | I24: =I23/I27 -> 0.0044152342 | J24: =J23/J27 -> 0.026835615 | K24: =K23/K27 -> 0.060680481 | ... O24: =O23/O27 -> 0.13640341
C25: Other Assets | D25: 88.52 | E25: 269.3 | F25: 337.14 | G25: 467.49 | H25: 426.44 | I25: 483.31 | J25: 330.49 | K25: 103.92 | L25: 38.6 | M25: 34.21 | N25: 39.47 | O25: 30.54
C26: Other Asset to Total Assets % | D26: =D25/D27 -> 0.80773793 | E26: =E25/E27 -> 0.98891011 | F26: =F25/F27 -> 0.89105614 | G26: =G25/G27 -> 0.92116256 | H26: =H25/H27 -> 0.86383341 | I26: =I25/I27 -> 0.8144759 | J26: =J25/J27 -> 0.74779952 | K26: =K25/K27 -> 0.53169609 | ... O26: =O25/O27 -> 0.33406257
C27: Total Assets | D27: 109.59 | E27: 272.32 | F27: 378.36 | G27: 507.5 | H27: 493.66 | I27: 593.4 | J27: 441.95 | K27: 195.45 | L27: 118.43 | M27: 108.87 | N27: 105.76 | O27: 91.42
C28: Asset Growth % | D28: 0 | E28: =(E27-D27)/D27 -> 1.4848983 | F28: =(F27-E27)/E27 -> 0.38939483 | G28: =(G27-F27)/F27 -> 0.34131515 | H28: =(H27-G27)/G27 -> -0.027270936 | I28: =(I27-H27)/H27 -> 0.20204189 | J28: =(J27-I27)/I27 -> -0.25522413 | K28: =(K27-J27)/J27 -> -0.5577554 | L28: =(L27-K27)/K27 -> -0.39406498 | ... O28: =(O27-N27)/N27 -> -0.13559002

Sheet CASH FLOW ANALYSIS
C3: CASH FLOW ANALYSIS
C4: Consolidated Figures in Rs. Crores
C5: PARTICULARS | D5: 2014 | E5: 2015 | F5: 2016 | G5: 2017 | H5: 2018 | I5: 2019 | J5: 2020 | K5: 2021 | L5: 2022 | M5: 2023 | N5: 2024 | O5: 2025
C6: Cash from Operating Activity (CFO) | D6: -4.03 | E6: -31.47 | F6: 0.8 | G6: 14.12 | H6: -4.33 | I6: 45.23 | J6: 25.59 | K6: 1.06 | L6: -1.16 | M6: 1.21 | N6: 4.81 | O6: -8.4
C7: CFO Growth % | D7: 0 | E7: =(E6-D6)/D6 -> 6.808933 | F7: =(F6-E6)/E6 -> -1.025421 | G7: =(G6-F6)/F6 -> 16.65 | H7: =(H6-G6)/G6 -> -1.3066572 | I7: =(I6-H6)/H6 -> -11.445727 | J7: =(J6-I6)/I6 -> -0.43422507 | K7: =(K6-J6)/J6 -> -0.95857757 | L7: =(L6-K6)/K6 -> -2.0943396 | ... O7: =(O6-N6)/N6 -> -2.7463617
C8: Cash from Investing Activity (CFI) | D8: -8.73 | E8: 17.42 | F8: -38.14 | G8: -56.12 | H8: 6.37 | I8: -49.15 | J8: 8.35 | K8: 3.4 | L8: 0.58 | M8: -0.07 | N8: 0.82 | O8: 0.2
C9: CFI Growth % | D9: 0 | E9: =(E8-D8)/D8 -> -2.9954181 | F9: =(F8-E8)/E8 -> -3.1894374 | G9: =(G8-F8)/F8 -> 0.47142108 | H9: =(H8-G8)/G8 -> -1.1135068 | I9: =(I8-H8)/H8 -> -8.7158556 | J9: =(J8-I8)/I8 -> -1.1698881 | K9: =(K8-J8)/J8 -> -0.59281437 | L9: =(L8-K8)/K8 -> -0.82941176 | ... O9: =(O8-N8)/N8 -> -0.75609756
C10: Cash from Financing Activity (CFF) | D10: 13.53 | E10: 16.97 | F10: 38.74 | G10: 40.36 | H10: 0.13 | I10: 3.3 | J10: -34.19 | K10: -4.94 | L10: 0.17 | M10: 0.67 | N10: 0 | O10: 0
C11: CFF Growth % | D11: 0 | E11: =(E10-D10)/D10 -> 0.25424982 | F11: =(F10-E10)/E10 -> 1.2828521 | G11: =(G10-F10)/F10 -> 0.041817243 | H11: =(H10-G10)/G10 -> -0.99677899 | I11: =(I10-H10)/H10 -> 24.384615 | J11: =(J10-I10)/I10 -> -11.360606 | K11: =(K10-J10)/J10 -> -0.85551331 | L11: =(L10-K10)/K10 -> -1.034413 | ... N11: =(N10-M10)/M10 -> -1 | O11: 0
C12: Net Cash Flow | D12: 0.77 | E12: 2.93 | F12: 1.4 | G12: -1.64 | H12: 2.17 | I12: -0.63 | J12: -0.25 | K12: -0.48 | L12: -0.42 | M12: 1.81 | N12: 5.63 | O12: -8.2
C13: Net Cash Flow Growth % | D13: 0 | E13: =(E12-D12)/D12 -> 2.8051948 | F13: =(F12-E12)/E12 -> -0.5221843 | G13: =(G12-F12)/F12 -> -2.1714286 | H13: =(H12-G12)/G12 -> -2.3231707 | I13: =(I12-H12)/H12 -> -1.2903226 | J13: =(J12-I12)/I12 -> -0.6031746 | K13: =(K12-J12)/J12 -> 0.92 | L13: =(L12-K12)/K12 -> -0.125 | ... O13: =(O12-N12)/N12 -> -2.4564831
C14: Free Cash Flow (FCF) | D14: -4.1 | E14: -33.98 | F14: -1.72 | G14: -23.37 | H14: -37.55 | I14: -6.06 | J14: 20.1 | K14: 4.96 | L14: -0.73 | M14: 1.21 | N14: 4.81 | O14: -8.4
C15: FCF Growth % | D15: 0 | E15: =(E14-D14)/D14 -> 7.2878049 | F15: =(F14-E14)/E14 -> -0.94938199 | G15: =(G14-F14)/F14 -> 12.587209 | H15: =(H14-G14)/G14 -> 0.6067608 | I15: =(I14-H14)/H14 -> -0.83861518 | J15: =(J14-I14)/I14 -> -4.3168317 | K15: =(K14-J14)/J14 -> -0.75323383 | L15: =(L14-K14)/K14 -> -1.1471774 | ... O15: =(O14-N14)/N14 -> -2.7463617
C16: CFO / OP | D16: -0.62 | E16: -2.02 | F16: 0.09 | G16: 0.3 | H16: -0.02 | I16: 0.6 | J16: -0.22 | K16: -0.01 | L16: 0.02 | M16: -0.17 | N16: -2.13 | O16: 7.24

Sheet HORIZONTAL ANALYSIS
C3: HORIZONTAL ANALYSIS
C4: PARTICULERS | G4: BASE YEAR ANALYSIS (%) | J4: ANNUAL GROWTH (%)
C5: YEAE | D5: REVENUE | E5: EXPENCE | F5: PROFIT | G5: REVENUE | H5: EXPENCE | I5: PROFIT | J5: REVENUE | K5: EXPENCE | L5: PROFIT
C6: 2014 | D6: 427.75 | E6: 421.83 | F6: 1.73 | G6: 1 | H6: 1 | I6: 1 | J6: 0 | K6: 0 | L6: 0
C7: 2015 | D7: 978.84 | E7: 963.71 | F7: 6.18 | G7: =D7/D6 -> 2.288346 | H7: =E7/E6 -> 2.2845933 | I7: =(F7/F6)*100 -> 357.22543 | J7: =(D7-D6)/D6 -> 1.288346 | K7: =(E7-E6)/E6 -> 1.2845933 | L7: =(F7-F6)/F6 -> 2.5722543
C8: 2016 | D8: 1270.19 | E8: 1241.47 | F8: 14.93 | G8: =D8/D6 -> 2.9694681 | H8: =E8/E6 -> 2.9430576 | I8: =(F8/F6)*100 -> 863.00578 | J8: =(D8-D7)/D7 -> 0.29764824 | K8: =(E8-E7)/E7 -> 0.28821949 | L8: =(F8-F7)/F7 -> 1.4158576
C9: 2017 | D9: 1734.67 | E9: 1681.03 | F9: 35.84 | G9: =D9/D6 -> 4.0553361 | H9: =E9/E6 -> 3.9850888 | I9: =(F9/F6)*100 -> 2071.6763 | J9: =(D9-D8)/D8 -> 0.36567758 | K9: =(E9-E8)/E8 -> 0.35406413 | L9: =(F9-F8)/F8 -> 1.4005358
C10: 2018 | D10: 2033.13 | E10: 1975.34 | F10: 32.8 | G10: =D10/D6 -> 4.7530801 | H10: =E10/E6 -> 4.6827869 | I10: =(F10/F6)*100 -> 1895.9538 | J10: =(D10-D9)/D9 -> 0.17205578 | K10: =(E10-E9)/E9 -> 0.17507718 | L10: =(F10-F9)/F9 -> -0.084821429
C11: 2019 | D11: 1997.53 | E11: 1921.41 | F11: 36.67 | G11: =D11/D6 -> 4.6698539 | H11: =E11/E6 -> 4.5549392 | I11: =(F11/F6)*100 -> 2119.6532 | J11: =(D11-D10)/D10 -> -0.017509948 | K11: =(E11-E10)/E10 -> -0.027301629 | L11: =(F11-F10)/F10 -> 0.1179878
C12: 2020 | D12: 456.83 | E12: 574.77 | F12: -166.35 | G12: =D12/D6 -> 1.0679836 | H12: =E12/E6 -> 1.3625631 | I12: =(F12/F6)*100 -> -9615.6069 | J12: =(D12-D11)/D11 -> -0.77130256 | K12: =(E12-E11)/E11 -> -0.70086031 | L12: =(F12-F11)/F11 -> -5.5364058
C13: 2021 | D13: 70.8 | E13: 214 | F13: -156.95 | G13: =D13/D6 -> 0.16551724 | H13: =E13/E6 -> 0.50731337 | I13: =(F13/F6)*100 -> -9072.2543 | J13: =(D13-D12)/D12 -> -0.84501893 | K13: =(E13-E12)/E12 -> -0.62767716 | L13: =(F13-F12)/F12 -> -0.056507364
C14: 2022 | D14: 59.68 | E14: 119.93 | F14: -71.66 | G14: =D14/D6 -> 0.13952075 | H14: =E14/E6 -> 0.28430884 | I14: =(F14/F6)*100 -> -4142.1965 | J14: =(D14-D13)/D13 -> -0.15706215 | K14: =(E14-E13)/E13 -> -0.43957944 | L14: =(F14-F13)/F13 -> -0.54342147
C15: 2023 | D15: 23.02 | E15: 29.95 | F15: -17.19 | G15: =D15/D6 -> 0.053816482 | H15: =E15/E6 -> 0.071000166 | I15: =(F15/F6)*100 -> -993.64162 | J15: =(D15-D14)/D14 -> -0.61427614 | K15: =(E15-E14)/E14 -> -0.75027099 | L15: =(F15-F14)/F14 -> -0.76011722
C16: 2024 | D16: 2.3 | E16: 4.56 | F16: -9.22 | G16: =D16/D6 -> 0.0053769725 | H16: =E16/E6 -> 0.010810042 | I16: =(F16/F6)*100 -> -532.94798 | J16: =(D16-D15)/D15 -> -0.90008688 | K16: =(E16-E15)/E15 -> -0.84774624 | L16: =(F16-F15)/F15 -> -0.46364165
C17: 2025 | D17: 0.98 | E17: 2.14 | F17: -6.44 | G17: =D17/D6 -> 0.0022910579 | H17: =E17/E6 -> 0.0050731337 | I17: =(F17/F6)*100 -> -372.25434 | J17: =(D17-D16)/D16 -> -0.57391304 | K17: =(E17-E16)/E16 -> -0.53070175 | L17: =(F17-F16)/F16 -> -0.30151844

Sheet VERTICAL ANALYSIS
C3: VERTICAL ANALYSIS
C4: YEAR | D4: REVENUE | E4: EXPENSES | F4: NET PROFIT | G4: EXPENSES AS % OF REVENUE | H4: NET PROFIT AS % OF REVENUE
C5: 2014 | D5: 427.75 | E5: 421.83 | F5: 1.73 | G5: =(E5/D5) -> 0.98616014 | H5: =(F5/D5) -> 0.0040444185
C6: 2015 | D6: 978.84 | E6: 963.71 | F6: 6.18 | G6: =(E6/D6) -> 0.98454293 | H6: =(F6/D6) -> 0.0063135957
C7: 2016 | D7: 1270.19 | E7: 1241.47 | F7: 14.93 | G7: =(E7/D7) -> 0.97738921 | H7: =(F7/D7) -> 0.011754147
C8: 2017 | D8: 1734.67 | E8: 1681.03 | F8: 35.84 | G8: =(E8/D8) -> 0.96907769 | H8: =(F8/D8) -> 0.02066099
C9: 2018 | D9: 2033.13 | E9: 1975.34 | F9: 32.8 | G9: =(E9/D9) -> 0.97157585 | H9: =(F9/D9) -> 0.016132761
C10: 2019 | D10: 1997.53 | E10: 1921.41 | F10: 36.67 | G10: =(E10/D10) -> 0.96189294 | H10: =(F10/D10) -> 0.018357672
C11: 2020 | D11: 456.83 | E11: 574.77 | F11: -166.35 | G11: =(E11/D11) -> 1.2581704 | H11: =(F11/D11) -> -0.36413983
C12: 2021 | D12: 70.8 | E12: 214 | F12: -156.95 | G12: =(E12/D12) -> 3.0225989 | H12: =(F12/D12) -> -2.2168079
C13: 2022 | D13: 59.68 | E13: 119.93 | F13: -71.66 | G13: =(E13/D13) -> 2.0095509 | H13: =(F13/D13) -> -1.2007373
C14: 2023 | D14: 23.02 | E14: 29.95 | F14: -17.19 | G14: =(E14/D14) -> 1.3010426 | H14: =(F14/D14) -> -0.74674196
C15: 2024 | D15: 2.3 | E15: 4.56 | F15: -9.22 | G15: =(E15/D15) -> 1.9826087 | H15: =(F15/D15) -> -4.0086957
C16: 2025 | D16: 0.98 | E16: 2.14 | F16: -6.44 | G16: =(E16/D16) -> 2.1836735 | H16: =(F16/D16) -> -6.5714286

Sheet RATIO ANALYSIS
B3: RATIO ANALYSIS
B4: RATIOS | C4: 41699 | D4: 42064 | E4: 42430 | F4: 42795 | G4: 43160 | H4: 43525 | I4: 43891 | J4: 44256 | K4: 44621 | L4: 44986 | M4: 45352 | N4: 45717
B5: PROFITABILITY RATIOS
B6: OPERATING PROFIT MARGIN | C6: ='PROFIT & LOSS'!D8/'PROFIT & LOSS'!D6 -> 0.01383986 | D6: ='PROFIT & LOSS'!E8/'PROFIT & LOSS'!E6 -> 0.015457072 | E6: ='PROFIT & LOSS'!F8/'PROFIT & LOSS'!F6 -> 0.022610791 | F6: ='PROFIT & LOSS'!G8/'PROFIT & LOSS'!G6 -> 0.030922308 | G6: ='PROFIT & LOSS'!H8/'PROFIT & LOSS'!H6 -> 0.028424154 | H6: ='PROFIT & LOSS'!I8/'PROFIT & LOSS'!I6 -> 0.038107062 | I6: ='PROFIT & LOSS'!J8/'PROFIT & LOSS'!J6 -> -0.25817044 | J6: ='PROFIT & LOSS'!K8/'PROFIT & LOSS'!K6 -> -2.0225989 | ... N6: ='PROFIT & LOSS'!O8/'PROFIT & LOSS'!O6 -> -1.1836735
B7: NET PROFIT MARGIN | C7: ='PROFIT & LOSS'!D15/'PROFIT & LOSS'!D6 -> 0.0040444185 | D7: ='PROFIT & LOSS'!E15/'PROFIT & LOSS'!E6 -> 0.0063135957 | E7: ='PROFIT & LOSS'!F15/'PROFIT & LOSS'!F6 -> 0.011754147 | F7: ='PROFIT & LOSS'!G15/'PROFIT & LOSS'!G6 -> 0.02066099 | G7: ='PROFIT & LOSS'!H15/'PROFIT & LOSS'!H6 -> 0.016132761 | H7: ='PROFIT & LOSS'!I15/'PROFIT & LOSS'!I6 -> 0.018357672 | I7: ='PROFIT & LOSS'!J15/'PROFIT & LOSS'!J6 -> -0.36413983 | J7: ='PROFIT & LOSS'!K15/'PROFIT & LOSS'!K6 -> -2.2168079 | ... N7: ='PROFIT & LOSS'!O15/'PROFIT & LOSS'!O6 -> -6.5714286
B8: RETURN ON EQUITY (ROE) | C8: ='PROFIT & LOSS'!D15/'BALANCE SHEET ANALYSIS'!D10 -> 0.040411119 | D8: ='PROFIT & LOSS'!E15/'BALANCE SHEET ANALYSIS'!E10 -> 0.12821577 | E8: ='PROFIT & LOSS'!F15/'BALANCE SHEET ANALYSIS'!F10 -> 0.23857462 | F8: ='PROFIT & LOSS'!G15/'BALANCE SHEET ANALYSIS'!G10 -> 0.24308193 | G8: ='PROFIT & LOSS'!H15/'BALANCE SHEET ANALYSIS'!H10 -> 0.14305652 | H8: ='PROFIT & LOSS'!I15/'BALANCE SHEET ANALYSIS'!I10 -> 0.13646682 | I8: ='PROFIT & LOSS'!J15/'BALANCE SHEET ANALYSIS'!J10 -> -1.5314859 | J8: ='PROFIT & LOSS'!K15/'BALANCE SHEET ANALYSIS'!K10 -> 3.1289872 | ... N8: ='PROFIT & LOSS'!O15/'BALANCE SHEET ANALYSIS'!O10 -> 0.041709845
B9: RETURN ON ASSETS (ROA) | C9: ='PROFIT & LOSS'!D15/'BALANCE SHEET'!D15 -> 0.015786112 | D9: ='PROFIT & LOSS'!E15/'BALANCE SHEET'!E15 -> 0.02269389 | E9: ='PROFIT & LOSS'!F15/'BALANCE SHEET'!F15 -> 0.039459774 | F9: ='PROFIT & LOSS'!G15/'BALANCE SHEET'!G15 -> 0.07062069 | G9: ='PROFIT & LOSS'!H15/'BALANCE SHEET'!H15 -> 0.066442491 | H9: ='PROFIT & LOSS'!I15/'BALANCE SHEET'!I15 -> 0.061796427 | I9: ='PROFIT & LOSS'!J15/'BALANCE SHEET'!J15 -> -0.37640005 | J9: ='PROFIT & LOSS'!K15/'BALANCE SHEET'!K15 -> -0.80301867 | ... N9: ='PROFIT & LOSS'!O15/'BALANCE SHEET'!O15 -> -0.070444104
B10: LEVERAGE / SOLVENCY RATIOS
B11: DEBT TO ASSETS RATIO | C11: ='BALANCE SHEET'!D8/'BALANCE SHEET'!D15 -> 0.23898166 | D11: ='BALANCE SHEET'!E8/'BALANCE SHEET'!E15 -> 0.18783049 | E11: ='BALANCE SHEET'!F8/'BALANCE SHEET'!F15 -> 0.26976953 | F11: ='BALANCE SHEET'!G8/'BALANCE SHEET'!G15 -> 0.29757635 | G11: ='BALANCE SHEET'!H8/'BALANCE SHEET'!H15 -> 0.24445975 | H11: ='BALANCE SHEET'!I8/'BALANCE SHEET'!I15 -> 0.24944388 | I11: ='BALANCE SHEET'!J8/'BALANCE SHEET'!J15 -> 0.53868085 | J11: ='BALANCE SHEET'!K8/'BALANCE SHEET'!K15 -> 1.1929394 | ... N11: ='BALANCE SHEET'!O8/'BALANCE SHEET'!O15 -> 2.5798512
B12: MARKET RATIOS
B13: EPS | C13: 1.59 | D13: 5.67 | E13: 13.7 | F13: 26.67 | G13: 24.41 | H13: 27.29 | I13: -106.11 | J13: -100.12 | K13: -45.71 | L13: -10.97 | M13: -5.88 | N13: -4.11
B14: CASH FLOW RATIOS
B15: CFO / OP | C15: =C17-62% -> -0.62 | D15: -2.02 | E15: 0.09 | F15: 0.3 | G15: -0.02 | H15: 0.6 | I15: -0.22 | J15: -0.01 | K15: 0.02 | L15: -0.17 | M15: -2.13 | N15: 7.24

Sheet TREND ANALYSIS
B11: YEAR | C11: REVENUE (₹ Cr) | D11: GROWTH %
B12: 2014 | C12: 427.75 | D12: -
B13: 2015 | C13: 978.84 | D13: 1.2883
B14: 2016 | C14: 1270.19 | D14: 0.2976
B15: 2017 | C15: 1734.67 | D15: 0.3657
B16: 2018 | C16: 2033.13 | D16: 0.1721
B17: 2019 | C17: 1997.53 | D17: -0.0175
B18: 2020 | C18: 456.83 | D18: -0.7713
B19: 2021 | C19: 70.8 | D19: -0.845
B20: 2022 | C20: 59.68 | D20: -0.1571
B21: 2023 | C21: 23.02 | D21: -0.6143
B22: 2024 | C22: 2.3 | D22: -0.9001
B23: 2025 | C23: 0.98 | D23: -0.5739
B40: YEAR | C40: OPERATING PROFIT | D40: NET PROFIT
B41: 2014 | C41: 5.92 | D41: 1.73
B42: 2015 | C42: 15.13 | D42: 6.18
B43: 2016 | C43: 28.72 | D43: 14.93
B44: 2017 | C44: 53.64 | D44: 35.84
B45: 2018 | C45: 57.79 | D45: 32.8
B46: 2019 | C46: 76.12 | D46: 36.67
B47: 2020 | C47: -117.94 | D47: -166.35
B48: 2021 | C48: -143.2 | D48: -156.95
B49: 2022 | C49: -60.25 | D49: -71.66
B50: 2023 | C50: -6.93 | D50: -17.19
B51: 2024 | C51: -2.26 | D51: -9.22
B52: 2025 | C52: -1.16 | D52: -6.44
B68: YEAR | C68: TOTAL ASSETS (₹ Cr)
B69: 2014 | C69: 109.59
B70: 2015 | C70: 272.32
B71: 2016 | C71: 378.36
B72: 2017 | C72: 507.5
B73: 2018 | C73: 493.66
B74: 2019 | C74: 593.4
B75: 2020 | C75: 441.95
B76: 2021 | C76: 195.45
B77: 2022 | C77: 118.43
B78: 2023 | C78: 108.87
B79: 2024 | C79: 105.76
B80: 2025 | C80: 91.42
B97: YEAR | C97: TOTAL LIABILITIES (₹ Cr) | D97: BORROWINGS (₹ Cr)
...

Sheet BUSINESS PERFORMANCE ANALYSIS

Sheet INSIGHTS & RECOMMENDATIONS
AM1: s
